Workbook

Sheet Kiểm toán trong ngày
A1: KIỂM TOÁN TRONG NGÀY :
A2: TIỀN KÉT | B2: 1581640 | C2: CHI
A3: DOANH THU | B3: 0 | C3: SỐ TIỀN | D3: NƠI CHI
A4: TỔNG TIỀN | B4: =SUM(B2:B3) -> 1581640
A5: SHIP | B5: 0
A6: SHIP BƯU ĐIỆN | B6: 0
A7: TRẢ HÀNG | B7: 0
A8: TT ĐIỂM | B8: 0
A9: TỔNG CHI | B9: =SUM(C4:C12) -> 0
A10: TỔNG TIỀN MẶT | B10: 0
A11: KHÁCH CK : | B11: 0
A12: CHÊNH LỆCH | B12: =B4-B5-B6-B7-B8-B9-B10-B11 -> 1581640
A15: KIỂM TOÁN TRONG NGÀY :
A16: TIỀN KÉT | C16: CHI
A17: DOANH THU | C17: SỐ TIỀN | D17: NƠI CHI
A18: TỔNG TIỀN
A19: SHIP
A20: SHIP BƯU ĐIỆN
A21: TRẢ HÀNG
A22: TT ĐIỂM
A23: TỔNG CHI
A24: TỔNG TIỀN MẶT
A25: KHÁCH CK :
A26: CHÊNH LỆCH

Sheet Chi tiết_2023_Mẫu
A1: CHI | B1: CHI TIẾT | C1: MỤC | E1: TỔNG THEO MỤC
A2: 45231 | E2: 食材 | F2: =SUMIF($C$3:$C$165,"=食材",$A$3:$A$165) -> 0 | G2: =SUM(F2:F8) -> 0
E3: 消耗品 | F3: =SUMIF($C$3:$C$165,"=消耗品",$A$3:$A$165) -> 0
E4: 家賃 | F4: =SUMIF($C$3:$C$165,"=家賃",$A$3:$A$165) -> 0
E5: 水代 | F5: =SUMIF($C$3:$C$165,"=水代",$A$3:$A$165) -> 0
E6: 電気代 | F6: =SUMIF($C$3:$C$165,"=電気代",$A$3:$A$165) -> 0
E7: 米 | F7: =SUMIF($C$3:$C$165,"=米",$A$3:$A$165) -> 0
A8: =SUM(A3:A7) -> 0 | E8: その他 | F8: =SUMIF($C$3:$C$165,"=その他",$A$3:$A$165) -> 0

Sheet Báo cáo tháng_Mẫu
A1: 日付 | C1: 売上 | D1: 支出 | E1: 入金 | F1: 不足 | G1: デリバリ | H1: 累計 | I1: 配達 | J1: 数 | L1: BÁO CÁO THÁNG
A2: 45139 | B2: 火 | C2: 388063 | D2: 91821 | E2: =C2-D2 -> 296242 | F2: -420 | G2: 31072 | H2: =E2+F2 -> 295822 | I2: 124532 | J2: 11 | L2: THU
A3: 45140 | B3: 水 | C3: 224971 | D3: 350405 | E3: =C3-D3 -> -125434 | F3: -202 | G3: 0 | H3: =H2+E3+F3 -> 170186 | I3: 0 | J3: 0 | L3: TỔNG | M3: SHIP BD | N3: SHIP | O3: Chênh lệch | P3: THANH TOÁN POINT
A4: 45141 | B4: 木 | C4: 208043 | D4: 330427 | E4: =C4-D4 -> -122384 | F4: -108 | G4: 12412 | H4: =H3+E4+F4 -> 47694 | I4: 96212 | J4: 8 | L4: =C33 -> 12758842 | M4: =G33 -> 559742 | N4: =I33 -> 5015906 | O4: =F33 -> -5934 | P4: 48431
A5: 45142 | B5: 金 | C5: 602364 | D5: 355522 | E5: =C5-D5 -> 246842 | F5: -417 | G5: 26408 | H5: =H4+E5+F5 -> 294119 | I5: 103472 | J5: 7 | M5: =M4/L4 -> 0.043870909 | N5: =N4/L4 -> 0.39313176 | O5: =O4/L4 -> -0.00046508923 | P5: =P4/L4 -> 0.0037958774
A6: 45143 | B6: 土 | C6: 464001 | D6: 89070 | E6: =C6-D6 -> 374931 | F6: -17 | G6: 0 | H6: =H5+E6+F6 -> 669033 | I6: 154763 | J6: 8 | L6: CHI
A7: 45144 | B7: 日 | C7: 288421 | D7: 33681 | E7: =C7-D7 -> 254740 | F7: -457 | G7: 0 | H7: =H6+E7+F7 -> 923316 | I7: 167530 | J7: 18 | L7: NHẬP HÀNG | M7: LƯƠNG | N7: TRẢ HÀNG | O7: Hỗ trợ ship BĐ | P7: TỔNG
A8: 45145 | B8: 月 | C8: 232104 | D8: 854538 | E8: =C8-D8 -> -622434 | F8: -729 | G8: 14272 | H8: =H7+E8+F8 -> 300153 | I8: 382120 | J8: 42 | L8: =D33 -> 11155239 | M8: =O16 -> 0 | N8: =Q19 -> 0 | O8: =M4*0.065 -> 36383.23 | P8: =SUM(L8:O8) -> 11191622
A9: 45146 | B9: 火 | C9: 353798 | D9: 197748 | E9: =C9-D9 -> 156050 | F9: -477 | G9: 12247 | H9: =H8+E9+F9 -> 455726 | I9: 112403 | J9: 6 | L9: LỢI NHUẬN | M9: =L4-P8 -> 1567219.8
A10: 45147 | B10: 水 | C10: 277820 | D10: 451545 | E10: =C10-D10 -> -173725 | F10: -327 | G10: 0 | H10: =H9+E10+F10 -> 281674 | I10: 0 | J10: 0 | L10: CHI TIẾT
A11: 45148 | B11: 木 | C11: 516600 | D11: 315292 | E11: =C11-D11 -> 201308 | F11: -410 | G11: 24720 | H11: =H10+E11+F11 -> 482572 | I11: 87650 | J11: 8 | L11: LƯƠNG - 給与
A12: 45149 | B12: 金 | C12: 889181 | D12: 215562 | E12: =C12-D12 -> 673619 | F12: -472 | G12: 10722 | H12: =H11+E12+F12 -> 1155719 | I12: 254690 | J12: 16 | L12: A. Giang | M12: A.Thái | N12: C.Hiền | O12: Nhàn | P12: Cưng | Q12: Nghĩa
A13: 45150 | B13: 土 | C13: 783523 | D13: 224503 | E13: =C13-D13 -> 559020 | F13: -311 | G13: 37489 | H13: =H12+E13+F13 -> 1714428 | I13: 210320 | J13: 15
A14: 45151 | B14: 日 | C14: 370475 | D14: 365034 | E14: =C14-D14 -> 5441 | F14: -774 | G14: 0 | H14: =H13+E14+F14 -> 1719095 | I14: 186542 | J14: 12 | L14: HỖ TRỢ
A15: 45152 | B15: 月 | C15: 456932 | D15: 982251 | E15: =C15-D15 -> -525319 | F15: -702 | G15: 17243 | H15: =H14+E15+F15 -> 1193074 | I15: 423412 | J15: 34
A16: 45153 | B16: 火 | C16: 430715 | D16: 81780 | E16: =C16-D16 -> 348935 | F16: -107 | G16: 15205 | H16: =H15+E16+F16 -> 1541902 | I16: 124328 | J16: 10 | L16: TỔNG | O16: =SUM(L13:Q13)+SUM(L15:Q15) -> 0
A17: 45154 | B17: 水 | C17: 463579 | D17: 78340 | E17: =C17-D17 -> 385239 | F17: 0 | G17: 45137 | H17: =H16+E17+F17 -> 1927141 | I17: 0 | J17: 0 | L17: CHI KHÁC - その他
A18: 45155 | B18: 木 | C18: 296872 | D18: 106660 | E18: =C18-D18 -> 190212 | F18: 0 | G18: 8882 | H18: =H17+E18+F18 -> 2117353 | I18: 192012 | J18: 12 | L18: TRẢ HÀNG | M18: HUỶ ĐƠN | N18: CHÊNH LỆCH | Q18: TỔNG
A19: 45156 | B19: 金 | C19: 584882 | D19: 768292 | E19: =C19-D19 -> -183410 | F19: 0 | G19: 38477 | H19: =H18+E19+F19 -> 1933943 | I19: 186312 | J19: 14 | Q19: =SUM(L19:P19) -> 0
A20: 45157 | B20: 土 | C20: 445331 | D20: 888408 | E20: =C20-D20 -> -443077 | F20: 0 | G20: 12712 | H20: =H19+E20+F20 -> 1490866 | I20: 146312 | J20: 11
A21: 45158 | B21: 日 | C21: 240602 | D21: 755010 | E21: =C21-D21 -> -514408 | F21: 0 | G21: 0 | H21: =H20+E21+F21 -> 976458 | I21: 78932 | J21: 8
A22: 45159 | B22: 月 | C22: 269988 | D22: 302465 | E22: =C22-D22 -> -32477 | F22: 0 | G22: 30904 | H22: =H21+E22+F22 -> 943981 | I22: 321267 | J22: 34
A23: 45160 | B23: 火 | C23: 320194 | D23: 115580 | E23: =C23-D23 -> 204614 | F23: 100 | G23: 12720 | H23: =H22+E23+F23 -> 1148695 | I23: 182712 | J23: 11
A24: 45161 | B24: 水 | C24: 227495 | D24: 268780 | E24: =C24-D24 -> -41285 | F24: -17 | G24: 0 | H24: =H23+E24+F24 -> 1107393 | I24: 0 | J24: 0
A25: 45162 | B25: 木 | C25: 320540 | D25: 191482 | E25: =C25-D25 -> 129058 | F25: -26 | G25: 42160 | H25: =H24+E25+F25 -> 1236425 | I25: 65901 | J25: 7
A26: 45163 | B26: 金 | C26: 870189 | D26: 590164 | E26: =C26-D26 -> 280025 | F26: -3 | G26: 22711 | H26: =H25+E26+F26 -> 1516447 | I26: 234518 | J26: 16
A27: 45164 | B27: 土 | C27: 584302 | D27: 258720 | E27: =C27-D27 -> 325582 | F27: -42 | G27: 28802 | H27: =H26+E27+F27 -> 1841987 | I27: 154302 | J27: 12
A28: 45165 | B28: 日 | C28: 586819 | D28: 839672 | E28: =C28-D28 -> -252853 | F28: 12 | G28: 0 | H28: =H27+E28+F28 -> 1589146 | I28: 183621 | J28: 12
A29: 45166 | B29: 月 | C29: 239366 | D29: 302670 | E29: =C29-D29 -> -63304 | F29: 0 | G29: 27720 | H29: =H28+E29+F29 -> 1525842 | I29: 532102 | J29: 44
A30: 45167 | B30: 火 | C30: 219358 | D30: 195331 | E30: =C30-D30 -> 24027 | F30: -12 | G30: 40007 | H30: =H29+E30+F30 -> 1549857 | I30: 117621 | J30: 10
A31: 45168 | B31: 水 | C31: 245142 | D31: 224636 | E31: =C31-D31 -> 20506 | F31: -7 | G31: 0 | H31: =H30+E31+F31 -> 1570356 | I31: 0 | J31: 0
A32: 45169 | B32: 木 | C32: 357172 | D32: 329850 | E32: =C32-D32 -> 27322 | F32: -9 | G32: 47720 | H32: =H31+E32+F32 -> 1597669 | I32: 192320 | J32: 17
A33: TỔNG | C33: =SUM(C2:C32) -> 12758842 | D33: =SUM(D2:D32) -> 11155239 | E33: =SUM(E2:E32) -> 1603603 | F33: =SUM(F2:F32) -> -5934 | G33: =SUM(G2:G32) -> 559742 | H33: =H32 -> 1597669 | I33: =SUM(I2:I32) -> 5015906 | J33: =SUM(J2:J32) -> 403

Sheet Mẫu 売り上げ
A1: 日付 | C1: 売上 | D1: CHI | E1: THU | F1: THIẾU | G1: SHIP BĐ | H1: LUỸ KẾ | I1: SHIP
A2: 45200 | B2: 水
A3: 45201 | B3: 木
A4: 45202 | B4: 金
A5: 45203 | B5: 土
A6: 45204 | B6: 日
A7: 45205 | B7: 月
A8: 45206 | B8: 火
A9: 45207 | B9: 水
A10: 45208 | B10: 木
A11: 45209 | B11: 金
A12: 45210 | B12: 土
A13: 45211 | B13: 日
... A31: 45229 | B31: 木

Sheet Hoá đơn_2023_5
A1: 日付： 01/05/2023(月曜日)
A2: 売り上げ
A3: 金額 | B3: 支払先 | C3: 詳細
A4: 20330 | B4: 三島株 | C4: 75kg Chân gà
A5: 21190 | B5: Kome | C5: G7(2x24)+Bột canh (2x40)+Miến (1x50)
A6: 29800 | B6: Sachan 株 | C6: 60kg Lạc
A7: 61179 | B7: THAK 株 | C7: Vịt (30) + Bắp heo (28.72)
A8: 44370 | B8: TRADIFOOD | C8: Gà ủ muối (50)
A9: 合計 | C9: =SUM(A4:A8) -> 176869
A10: チャージ
A11: ポイント支払い
A12: レジ
A13: 入金
A14: 不足
A16: 日付： 02/05/2023(火曜日)
A17: 売り上げ
A18: 金額 | B18: 支払先 | C18: 詳細
A19: 2110 | C19: Phí ship Mướp
A20: 9246 | B20: ナフコ | C20: Túi bóng
A21: 142240 | C21: Hoa quả tháng 4
A22: 96300 | B22: ベトナムハウス | C22: 50kg ớt + 30 cây Thăng Long
A23: 合計 | C23: =SUM(A19:A22) -> 249896
A24: チャージ
A25: ポイント支払い
A26: レジ
A27: 入金
A28: 不足
A30: 日付： 03/05/2023(水曜日)
A31: 売り上げ
A32: 金額 | B32: 支払先 | C32: 詳細
A33: 24441 | B33: フリチク | C33: 60 gà đông lạnh
A34: 550 | B34: ダイソ | C34: Băng keo
A35: 59170 | B35: Yến Ming 株 | C35: Rau
A36: 21450 | C36: 22 Gà ủ muối
A37: 2505 | C37: Phí ship Xoài
A38: 合計 | C38: =SUM(A33:A37) -> 108116
A39: チャージ
A40: ポイント支払い
A41: レジ
A42: 入金
...

Sheet 2022_11
B2: Tháng trước | C2: 400000
B4: 日付 | C4: Doanh thu | D4: Trả hàng | E4: Chi | F4: Chi tiết | G4: Tổng chi | H4: Luỹ kế
B5: 44866 | C5: 329962 | E5: 410024 | F5: Đồ khô | G5: =SUM(E5) -> 410024 | H5: =C2+C5 -> 729962
B6: 44867 | C6: 165251 | E6: 94550 | F6: Vietcook | G6: =SUM(E6) -> 94550 | H6: =H5+C6-D6-G6 -> 800663
B7: 44868 | C7: 365411 | E7: 135700 | F7: Vietcook | G7: =E7 -> 135700 | H7: =H6+C7-D7-G7 -> 1030374
B8: 44869 | C8: 342540 | E8: 92550 | F8: Vietcook | G8: =SUM(E8:E9) -> 114440 | H8: =H7+C8-D8-G8 -> 1258474
E9: 21890 | F9: Gà lộn 2 kiện | H9: =H8+C9-D9-G9 -> 1258474
B10: 44870 | C10: 343069 | G10: =E10 -> 0 | H10: =H9+C10-D10-G10 -> 1601543
B11: 44871 | C11: 458613 | E11: 64490 | F11: Vietcook | G11: =E11 -> 64490 | H11: =H10+C11-D11-G11 -> 1995666
B12: 44872 | C12: 314471 | E12: 163470 | F12: Vietcook | G12: =E12 -> 163470 | H12: =H11+C12-D12-G12 -> 2146667
E13: 544817 | F13: Đồ khô | G13: =E13 -> 544817
B14: 44873 | C14: 226228 | E14: 30000 | F14: Thi công điện | G14: =SUM(E14:E16) -> 32990 | H14: =H12+C14-D14-G14 -> 2339905
E15: 1830 | F15: Phí ship rau | H15: =H14+C15-D15-G15 -> 2339905
E16: 1160 | F16: Phí ship rau | H16: =H15+C16-D16-G16 -> 2339905
B17: 44874 | C17: 207346 | E17: 10730 | F17: Gà lộn 1 kiện | G17: =E17 -> 10730 | H17: =H16+C17-D17-G17 -> 2536521
B18: 44875 | C18: 178730 | E18: 2110 | F18: Phí ship rau | G18: =SUM(E18:E21) -> 107702 | H18: =H17+C18-D18-G18 -> 2607549
E19: 1830 | F19: Phí ship rau | H19: =H18+C19-D19-G19 -> 2607549
E20: 54700 | F20: Thịt heo | H20: =H19+C20-D20-G20 -> 2607549
E21: 49062 | F21: Xoài | H21: =H20+C21-D21-G21 -> 2607549
B22: 44876 | C22: 302120 | D22: 9888 | E22: 43160 | F22: Vịt | G22: =SUM(E22:E26) -> 92176 | H22: =H21+C22-D22-G22 -> 2807605
E23: 21130 | F23: Gà lộn 2 kiện | H23: =H22+C23-D23-G23 -> 2807605
E24: 23668 | F24: Hành khô | H24: =H23+C24-D24-G24 -> 2807605
E25: 1830 | F25: Phí ship ổi | H25: =H24+C25-D25-G25 -> 2807605
E26: 2388 | F26: Cồn rửa | H26: =#REF!+C26-D26-G26 -> #REF!
B27: 44877 | C27: 417626 | E27: 572505 | F27: Đồ khô | G27: =SUM(E27:E34) -> 967537 | H27: =H26+C27-D27-G27 -> #REF!
E28: 29000 | F28: Rau | H28: =H27+C28-D28-G28 -> #REF!
E29: 249100 | F29: Thịt | H29: =H28+C29-D29-G29 -> #REF!
E30: 8000 | F30: Rau | H30: =H29+C30-D30-G30 -> #REF!
E31: 43110 | F31: Chè sầu-Bông lan | H31: =H30+C31-D31-G31 -> #REF!
E32: 64490 | F32: Vietcook | H32: =H31+C32-D32-G32 -> #REF!
E33: 770 | F33: Túi bóng | H33: =H32+C33-D33-G33 -> #REF!
E34: 562 | F34: Túi bóng | H34: =H33+C34-D34-G34 -> #REF!
B35: 44878 | C35: 414182 | E35: 163470 | F35: Vietcook | G35: =SUM(E35:E38) -> 356100 | H35: =H34+C35-D35-G35 -> #REF!
E36: 188620 | F36: Đông lạnh | H36: =H35+C36-D36-G36 -> #REF!
E37: 2400 | F37: Cải muối | H37: =H36+C37-D37-G37 -> #REF!
E38: 1610 | F38: Phí ship rau | H38: =H37+C38-D38-G38 -> #REF!
B39: 44879 | C39: 187564 | G39: =E39 -> 0 | H39: =H38+C39-D39-G39 -> #REF!
B40: 44880 | C40: 251319 | D40: 2947 | E40: 1654 | F40: Túi bóng | G40: =SUM(E40:E45) -> 36126 | H40: =H39+C40-D40-G40 -> #REF!
E41: 7980 | F41: Túi bóng | H41: =H40+C41-D41-G41 -> #REF!
E42: 10802 | F42: Mua cân | H42: =H41+C42-D42-G42 -> #REF!
...

Sheet 2023_2
A1: Tháng trước
A2: 日付 | C2: Doanh thu | D2: Tổng chi | E2: 小計 | F2: Luỹ kế | G2: 入金
A3: 44958 | B3: 水 | C3: 156900 | D3: 110325 | E3: =C3-D3 -> 46575 | F3: =E3 -> 46575
A4: 44959 | B4: 木 | C4: 349841 | D4: 108665 | E4: =C4-D4 -> 241176 | F4: =F3+E4 -> 287751
A5: 44960 | B5: 金 | C5: 243550 | D5: 163250 | E5: =C5-D5 -> 80300 | F5: =F4+E5 -> 368051
A6: 44961 | B6: 土 | C6: 423870 | D6: 28635 | E6: =C6-D6 -> 395235 | F6: =F5+E6 -> 763286
A7: 44962 | B7: 日 | C7: 390667 | D7: 334895 | E7: =C7-D7 -> 55772 | F7: =F6+E7 -> 819058
A8: 44963 | B8: 月 | C8: 150304 | D8: 122886 | E8: =C8-D8 -> 27418 | F8: =F7+E8 -> 846476
A9: 44964 | B9: 火 | C9: 253040 | D9: 652907 | E9: =C9-D9 -> -399867 | F9: =F8+E9 -> 446609
A10: 44965 | B10: 水 | C10: 242255 | D10: 262933 | E10: =C10-D10 -> -20678 | F10: =F9+E10 -> 425931
A11: 44966 | B11: 木 | C11: 161847 | D11: 128934 | E11: =C11-D11 -> 32913 | F11: =F10+E11 -> 458844
A12: 44967 | B12: 金 | C12: 286707 | D12: 206633 | E12: =C12-D12 -> 80074 | F12: =F11+E12 -> 538918
A13: 44968 | B13: 土 | C13: 384625 | D13: 318780 | E13: =C13-D13 -> 65845 | F13: =F12+E13 -> 604763
A14: 44969 | B14: 日 | C14: 342732 | D14: 56510 | E14: =C14-D14 -> 286222 | F14: =F13+E14 -> 890985
A15: 44970 | B15: 月 | C15: 194289 | D15: 448900 | E15: =C15-D15 -> -254611 | F15: =F14+E15 -> 636374
... A30: 44985 | B30: 火 | C30: 356126 | D30: 425439 | E30: =C30-D30 -> -69313 | F30: =F29+E30 -> 1227571
D31: 190000 | E31: =C31-D31 -> -190000 | F31: =F30+E31 -> 1037571
D32: =F155 -> 60000
C33: =SUM(C3:C30) -> 8197983 | D33: =F156 -> 6737507 | F33: =C33-D33 -> 1460476
A35: 領収書
A36: 日付 | C36: Nơi chi | D36: 金額 | E36: Chi Tiết | F36: Tổng | G36: 確認
A37: 44958 | B37: 水 | D37: 23555 | E37: Sườn già | F37: =SUM(D37:D41) -> 110325
D38: 5000 | E38: Nước mía
D39: 37900 | E39: Xoài
D40: 30400 | E40: Sả
D41: 13470 | E41: BLTM
A42: 44959 | B42: 木 | D42: 44700 | E42: Gà ủ muối | F42: =SUM(D42:D44) -> 108665
D43: 44900 | E43: Bún safoco
D44: 19065 | E44: Hành khô
A45: 44960 | B45: 金 | D45: 2110 | E45: Phí ship | F45: =SUM(D45:D47) -> 28635
D46: 5005 | E46: Túi bóng
D47: 21520 | E47: Ớt
A48: 44961 | B48: 土 | D48: 163250 | E48: Thịt heo | F48: =D48 -> 163250
A49: 44962 | B49: 日 | D49: 370 | F49: =SUM(D49:D52) -> 334895
C50: Vietcook | D50: 79560 | E50: Giò chả
D51: 28010 | E51: Gà ủ muối
C52: Xuân Shop | D52: 226955 | E52: Đồ khô
A53: 44963 | B53: 月 | D53: 27640 | E53: Bò húc | F53: =SUM(D53:D56) -> 122880
D54: 59660 | E54: Giò chả
D55: 16240 | E55: Numberone
...

Sheet 2023_3
A1: Tháng trước
A2: 日付 | C2: Doanh thu | D2: Tổng chi | E2: 小計 | F2: Luỹ kế | G2: 入金
A3: 44986 | B3: 水 | C3: 418832 | D3: =F38 -> 45569 | E3: =C3-D3 -> 373263 | F3: =E3 -> 373263
A4: 44987 | B4: 木 | C4: 289820 | D4: =F41 -> 83955 | E4: =C4-D4 -> 205865 | F4: =F3+E4 -> 579128
A5: 44988 | B5: 金 | C5: 589257 | D5: =F44 -> 190842 | E5: =C5-D5 -> 398415 | F5: =F4+E5 -> 977543
A6: 44989 | B6: 土 | C6: 463659 | D6: =F52 -> 263162 | E6: =C6-D6 -> 200497 | F6: =F5+E6 -> 1178040
A7: 44990 | B7: 日 | C7: 401658 | D7: =F61 -> 118683 | E7: =C7-D7 -> 282975 | F7: =F6+E7 -> 1461015
A8: 44991 | B8: 月 | C8: 195456 | D8: =F65 -> 996094 | E8: =C8-D8 -> -800638 | F8: =F7+E8 -> 660377
A9: 44992 | B9: 火 | C9: 185887 | D9: =F71 -> 245332 | E9: =C9-D9 -> -59445 | F9: =F8+E9 -> 600932
A10: 44993 | B10: 水 | C10: 243908 | D10: =F75 -> 176477 | E10: =C10-D10 -> 67431 | F10: =F9+E10 -> 668363
A11: 44994 | B11: 木 | C11: 196885 | D11: =F80 -> 127305 | E11: =C11-D11 -> 69580 | F11: =F10+E11 -> 737943
A12: 44995 | B12: 金 | C12: 416444 | D12: =F83 -> 41230 | E12: =C12-D12 -> 375214 | F12: =F11+E12 -> 1113157
A13: 44996 | B13: 土 | C13: 591768 | D13: =F85 -> 42446 | E13: =C13-D13 -> 549322 | F13: =F12+E13 -> 1662479
A14: 44997 | B14: 日 | C14: 386901 | D14: =F88 -> 871431 | E14: =C14-D14 -> -484530 | F14: =F13+E14 -> 1177949
A15: 44998 | B15: 月 | C15: 213669 | D15: =F95 -> 107786 | E15: =C15-D15 -> 105883 | F15: =F14+E15 -> 1283832
A16: 44999 | B16: 火 | C16: 286213 | D16: =F98 -> 184313 | E16: =C16-D16 -> 101900 | F16: =F15+E16 -> 1385732
A17: 45000 | B17: 水 | C17: 214192 | D17: =F103 -> 230206 | E17: =C17-D17 -> -16014 | F17: =F16+E17 -> 1369718
A18: 45001 | B18: 木 | C18: 181386 | D18: =F109 -> 144374 | E18: =C18-D18 -> 37012 | F18: =F17+E18 -> 1406730
A19: 45002 | B19: 金 | C19: 581148 | D19: =F115 -> 138200 | E19: =C19-D19 -> 442948 | F19: =F18+E19 -> 1849678
A20: 45003 | B20: 土 | C20: 360237 | D20: =F120 -> 235100 | E20: =C20-D20 -> 125137 | F20: =F19+E20 -> 1974815
A21: 45004 | B21: 日 | C21: 280605 | D21: =F125 -> 183908 | E21: =C21-D21 -> 96697 | F21: =F20+E21 -> 2071512
A22: 45005 | B22: 月 | C22: 261819 | D22: =F129 -> 662444 | E22: =C22-D22 -> -400625 | F22: =F21+E22 -> 1670887
A23: 45006 | B23: 火 | C23: 232191 | D23: =F133 -> 80970 | E23: =C23-D23 -> 151221 | F23: =F22+E23 -> 1822108
A24: 45007 | B24: 水 | C24: 169153 | D24: =F138 -> 72324 | E24: =C24-D24 -> 96829 | F24: =F23+E24 -> 1918937
A25: 45008 | B25: 木 | C25: 244680 | D25: =F139 -> 86060 | E25: =C25-D25 -> 158620 | F25: =F24+E25 -> 2077557
A26: 45009 | B26: 金 | C26: 438725 | D26: =F143 -> 114890 | E26: =C26-D26 -> 323835 | F26: =F25+E26 -> 2401392
A27: 45010 | B27: 土 | C27: 550730 | D27: =F146 -> 684758 | E27: =C27-D27 -> -134028 | F27: =F26+E27 -> 2267364
A28: 45011 | B28: 日 | C28: 340934 | D28: =F153 -> 38392 | E28: =C28-D28 -> 302542 | F28: =F27+E28 -> 2569906
A29: 45012 | B29: 月 | C29: 0 | D29: =F155 -> 42795 | E29: =C29-D29 -> -42795 | F29: =F28+E29 -> 2527111
A30: 45013 | B30: 火 | C30: 319435 | D30: =F156 -> 712172 | E30: =C30-D30 -> -392737 | F30: =F29+E30 -> 2134374
A31: 45014 | B31: 水 | C31: 282375 | D31: =F162 -> 259900 | E31: =C31-D31 -> 22475 | F31: =F30+E31 -> 2156849
A32: 45015 | B32: 木 | C32: 302199 | D32: =F165 -> 141888 | E32: =C32-D32 -> 160311 | F32: =F31+E32 -> 2317160
A33: 45016 | B33: 金 | C33: 705681 | D33: =F171 -> 315830 | E33: =C33-D33 -> 389851 | F33: =F32+E33 -> 2707011
D34: 708321 | E34: =C34-D34 -> -708321 | F34: =F33+E34 -> 1998690
A35: 合計 | C35: =SUM(C3:C33) -> 10345847 | D35: =SUM(D3:D33) -> 7638836
A36: 領収書
A37: 日付 | C37: Nơi chi | D37: 金額 | E37: Chi Tiết | F37: Tổng | G37: 確認
A38: 44986 | B38: 水 | C38: Chợ Sỹ Thak | D38: 17099 | E38: 20kg bắp heo | F38: =SUM(D38:D39) -> 45569
C39: Di An Di | D39: 28470 | E39: 18 BLTM+30 chè sầu + 20 chè dừa non
D40: 130000 | E40: Tiền nhà
...

Sheet 2023_4
A1: 日付 | C1: Doanh Thu | D1: Tổng Chi | E1: Ship BĐ | F1: Luỹ kế | G1: Ship
A2: 45017 | B2: 土 | C2: 392879 | D2: 180197 | E2: 0 | F2: =C2-D2 -> 212682 | G2: 50520
A3: 45018 | B3: 日 | C3: 288213 | D3: 206824 | E3: 17529 | F3: =C3-D3+F2 -> 294071 | G3: 0
A4: 45019 | B4: 月 | C4: 261646 | D4: 716462 | E4: 30200 | F4: =C4-D4+F3 -> -160745 | G4: 91849
A5: 45020 | B5: 火 | C5: 342457 | D5: 146387 | E5: 0 | F5: =C5-D5+F4 -> 35325 | G5: 182436
A6: 45021 | B6: 水 | C6: 194932 | D6: 1004590 | E6: 0 | F6: =C6-D6+F5 -> -774333 | G6: 72210
A7: 45022 | B7: 木 | C7: 344621 | D7: 533119 | E7: 0 | F7: =C7-D7+F6 -> -962831 | G7: 127167
A8: 45023 | B8: 金 | C8: 485949 | D8: 197708 | E8: 8324 | F8: =C8-D8+F7 -> -674590 | G8: 334341
A9: 45024 | B9: 土 | C9: 416374 | D9: 64412 | E9: 0 | F9: =C9-D9+F8 -> -322628 | G9: 64232
A10: 45025 | B10: 日 | C10: 324598 | D10: 391190 | E10: 0 | F10: =C10-D10+F9 -> -389220 | G10: 0
A11: 45026 | B11: 月 | C11: 215353 | D11: 63470 | E11: 20006 | F11: =C11-D11+F10 -> -237337 | G11: 75127
A12: 45027 | B12: 火 | C12: 392103 | D12: 24980 | E12: 0 | F12: =C12-D12+F11 -> 129786 | G12: 245247
A13: 45028 | B13: 水 | C13: 267178 | D13: 85764 | E13: 26712 | F13: =C13-D13+F12 -> 311200 | G13: 170179
A14: 45029 | B14: 木 | C14: 325349 | D14: 154349 | E14: 7602 | F14: =C14-D14+F13 -> 482200 | G14: 140212
... A18: 45033 | B18: 月 | C18: 194940 | D18: 289320 | E18: 13945 | F18: =C18-D18+F17 -> 485468 | G18: 79242
A19: 45034 | B19: 火 | C19: 254482 | D19: 80810 | E19: 0 | F19: 659140 | G19: 113538
A20: 45035 | B20: 水 | C20: 190349 | D20: 183857 | E20: 25612 | F20: =C20-D20+F19 -> 665632 | G20: 60322
A21: 45036 | B21: 木 | C21: 203693 | D21: 126930 | E21: 0 | F21: =C21-D21+F20 -> 742395 | G21: 82712
A22: 45037 | B22: 金 | C22: 425984 | D22: 484843 | E22: 0 | F22: =C22-D22+F21 -> 683536 | G22: 287918
A23: 45038 | B23: 土 | C23: 485848 | D23: 170451 | E23: 28248 | F23: =C23-D23+F22 -> 998933 | G23: 89224
A24: 45039 | B24: 日 | C24: 350968 | D24: 64428 | E24: 0 | F24: =C24-D24+F23 -> 1285473 | G24: 0
A25: 45040 | B25: 月 | C25: 144851 | D25: 676242 | E25: 21553 | F25: =C25-D25+F24 -> 754082 | G25: 32662
A26: 45041 | B26: 火 | C26: 256866 | D26: 25495 | E26: 36121 | F26: =C26-D26+F25 -> 985453 | G26: 171159
A27: 45042 | B27: 水 | C27: 427621 | D27: 98856 | E27: 17399 | F27: =C27-D27+F26 -> 1314218 | G27: 211339
A28: 45043 | B28: 木 | C28: 361633 | D28: 123933 | E28: 0 | F28: =C28-D28+F27 -> 1551918 | G28: 210273
A29: 45044 | B29: 金 | C29: 762448 | D29: 642585 | E29: 39001 | F29: =C29-D29+F28 -> 1671781 | G29: 487726
A30: 45045 | B30: 土 | C30: 409023 | D30: 161979 | E30: 10731 | F30: =C30-D30+F29 -> 1918825 | G30: 134108
A31: 45046 | B31: 日 | C31: 674794 | D31: 856629 | E31: 21643 | F31: =C31-D31+F30 -> 1736990 | G31: 15850
A32: TỔNG | C32: =SUM(C2:C31) -> 10638575 | D32: =SUM(D2:D31) -> 8901585 | E32: =SUM(E2:E31) -> 345622 | F32: =F31 -> 1736990 | G32: =SUM(G2:G31) -> 3954720
A33: BÁO CÁO THÁNG
C34: THU
C35: TỔNG | D35: SHIP BD | E35: SHIP
C36: =C32 -> 10638575 | D36: =E32 -> 345622 | E36: =G32 -> 3954720
D37: =D36/C36 -> 0.032487622 | E37: =E36/C36 -> 0.371734
C38: CHI
C39: NHẬP HÀNG | D39: LƯƠNG | E39: HỖ TRỢ SHIP | F39: TRẢ HÀNG | G39: TỔNG
C40: =D32 -> 8901585 | D40: =SUM(D47:G47) -> 518800 | E40: =D36*0.055 -> 19009.21 | F40: =SUM(D49:G49) -> 6414 | G40: =SUM(C40:F40) -> 9445808.2
C41: LỢI NHUẬN | D41: =C36-G40 -> 1192766.8
C42: CHI TIẾT
C43: LƯƠNG | D43: Anh Giang | E43: Anh Thái | F43: Nghĩa | G43: Khánh
...

Sheet 2023_5
A1: 日付 | C1: Doanh Thu | D1: Tổng Chi | E1: Ship BĐ | F1: Luỹ kế | G1: Ship | H1: Đơn
A2: 45047 | B2: 月 | C2: 395724 | D2: 176869 | E2: 0 | F2: =C2-D2 -> 218855 | G2: 168757 | H2: 12
A3: 45048 | B3: 火 | C3: 364455 | D3: 249869 | E3: 0 | F3: =C3-D3+F2 -> 333441 | G3: 57626 | H3: 9
A4: 45049 | B4: 水 | C4: 577062 | D4: 108116 | E4: 8289 | F4: =C4-D4+F3 -> 802387 | G4: 106124 | H4: 7
A5: 45050 | B5: 木 | C5: 536243 | D5: 313427 | E5: 0 | F5: =C5-D5+F4 -> 1025203 | G5: 110212 | H5: 8
A6: 45051 | B6: 金 | C6: 480165 | D6: 1426942 | E6: 0 | F6: =C6-D6+F5 -> 78426 | G6: 162021 | H6: 20
A7: 45052 | B7: 土 | C7: 279652 | D7: 113290 | E7: 0 | F7: =C7-D7+F6 -> 244788 | G7: 124320 | H7: 11
A8: 45053 | B8: 日 | C8: 248779 | D8: 184295 | E8: 25887 | F8: =C8-D8+F7 -> 309272 | G8: 0 | H8: 0
A9: 45054 | B9: 月 | C9: 239320 | D9: 63165 | E9: 0 | F9: =C9-D9+F8 -> 485427 | G9: 52430 | H9: 4
A10: 45055 | B10: 火 | C10: 247470 | D10: 592382 | E10: 31711 | F10: =C10-D10+F9 -> 140515 | G10: 73182 | H10: 8
A11: 45056 | B11: 水 | C11: 262362 | D11: 66890 | E11: 27852 | F11: =C11-D11+F10 -> 335987 | G11: 68420 | H11: 6
A12: 45057 | B12: 木 | C12: 219319 | D12: 177157 | E12: 8612 | F12: =C12-D12+F11 -> 378149 | G12: 80168 | H12: 10
A13: 45058 | B13: 金 | C13: 702894 | D13: 41121 | E13: 26511 | F13: =C13-D13+F12 -> 1039922 | G13: 444003 | H13: 41
A14: 45059 | B14: 土 | C14: 297040 | D14: 604873 | E14: 36574 | F14: =C14-D14+F13 -> 732089 | G14: 92164 | H14: 11
... A32: 45077 | B32: 水 | C32: 228910 | D32: 279199 | E32: 109080 | F32: =C32-D32+F31 -> 1235471 | G32: 0 | H32: 11
A33: TỔNG | C33: =SUM(C2:C32) -> 10551079 | D33: =SUM(D2:D32) -> 9315608 | E33: =SUM(E2:E32) -> 561525 | F33: =F32 -> 1235471 | G33: =SUM(G2:G32) -> 3474234 | H33: =SUM(H2:H32) -> 359
A34: BÁO CÁO THÁNG
C35: THU
C36: TỔNG | D36: SHIP BD | E36: SHIP | F36: THANH TOÁN POINT
C37: =C33 -> 10551079 | D37: =E33 -> 561525 | E37: =G33 -> 3474234 | F37: 76964
D38: =D37/C37 -> 0.053219675 | E38: =E37/C37 -> 0.3292776 | F38: =F37/C37 -> 0.0072944198
C39: CHI
C40: NHẬP HÀNG | D40: LƯƠNG | E40: HỖ TRỢ SHIP | F40: TRẢ HÀNG | G40: TỔNG
C41: =D33 -> 9315608 | D41: =SUM(D45:G45) -> 505750 | E41: =E33*0.057 -> 32006.925 | F41: =F52 -> 2644 | G41: =SUM(C41:F41) -> 9856008.9
C42: LỢI NHUẬN | D42: =C37-G41-F37 -> 618106.07
C43: CHI TIẾT
C44: LƯƠNG | D44: Anh Giang | E44: Anh Thái | F44: Nghĩa | G44: Khánh
D45: 250000 | E45: 60000 | F45: 172000 | G45: 23750
C46: THƯỞNG | D46: Anh Giang | E46: Anh Thái | F46: Nghĩa | G46: Khánh
D47: 0 | E47: 0 | F47: 0 | G47: 0
C48: TỔNG | D48: =D45+D47 -> 250000 | E48: =E45+E47 -> 60000 | F48: =F45+F47 -> 172000 | G48: =G45+G47 -> 23750
C49: TRẢ HÀNG | D49: ĐƠN 1 | E49: ĐƠN 2 | F49: ĐƠN 3 | G49: ĐƠN 4
D50: 800 | E50: 920 | F50: 924 | G50: 0
C51: Nội dung | D51: Gà lộn | E51: Tính nhầm | F51: Tai heo
C52: Tổng | F52: =SUM(D50:G50) -> 2644

Sheet 2023_6
A1: 日付 | C1: Doanh Thu | D1: Tổng Chi | E1: Ship BĐ | F1: Luỹ kế | G1: Ship | H1: Đơn
A2: 45078 | B2: 木 | C2: 165869 | D2: 66000 | E2: 0 | F2: =C2-D2 -> 99869 | G2: 70851 | H2: 6
A3: 45079 | B3: 金 | C3: 558838 | D3: 10520 | E3: 5188 | F3: =C3-D3+F2 -> 648187 | G3: 370484 | H3: 38
A4: 45080 | B4: 土 | C4: 454777 | D4: 100383 | E4: 19543 | F4: =C4-D4+F3 -> 1002581 | G4: 106124 | H4: 7
A5: 45081 | B5: 日 | C5: 572681 | D5: 91615 | E5: 21778 | F5: =C5-D5+F4 -> 1483647 | G5: 0 | H5: 0
A6: 45082 | B6: 月 | C6: 277611 | D6: 1184125 | E6: 52904 | F6: =C6-D6+F5 -> 577133 | G6: 98727 | H6: 14
A7: 45083 | B7: 火 | C7: 278988 | D7: 92524 | E7: 15285 | F7: =C7-D7+F6 -> 763597 | G7: 141620 | H7: 16
A8: 45084 | B8: 水 | C8: 255712 | D8: 553685 | E8: 0 | F8: =C8-D8+F7 -> 465624 | G8: 125555 | H8: 14
A9: 45085 | B9: 木 | C9: 231880 | D9: 212778 | E9: 0 | F9: =C9-D9+F8 -> 484726 | G9: 144229 | H9: 17
A10: 45086 | B10: 金 | C10: 674965 | D10: 286339 | E10: 17425 | F10: =C10-D10+F9 -> 873352 | G10: 462124 | H10: 34
A11: 45087 | B11: 土 | C11: 663609 | D11: 292901 | E11: 10334 | F11: =C11-D11+F10 -> 1244060 | G11: 201720 | H11: 13
A12: 45088 | B12: 日 | C12: 491942 | D12: 103690 | E12: 30342 | F12: =C12-D12+F11 -> 1632312 | G12: 0 | H12: 0
A13: 45089 | B13: 月 | C13: 225920 | D13: 641010 | E13: 21941 | F13: =C13-D13+F12 -> 1217222 | G13: 92142 | H13: 8
A14: 45090 | B14: 火 | C14: 276059 | D14: 40493 | E14: 2921 | F14: =C14-D14+F13 -> 1452788 | G14: 102342 | H14: 9
... A31: 45107 | B31: 金 | C31: 636145 | D31: 501894 | E31: 20320 | F31: =C31-D31+F30 -> 2623458 | G31: 457329 | H31: 45
A33: TỔNG | C33: =SUM(C2:C32) -> 11588760 | D33: =SUM(D2:D32) -> 8965302 | E33: =SUM(E2:E32) -> 433398 | F33: =F31 -> 2623458 | G33: =SUM(G2:G32) -> 4494386 | H33: =SUM(H2:H32) -> 397
A34: BÁO CÁO THÁNG
C35: THU
C36: TỔNG | D36: SHIP BD | E36: SHIP | F36: THANH TOÁN POINT
C37: =C33 -> 11588760 | D37: =E33 -> 433398 | E37: =G33 -> 4494386 | F37: 125814
D38: =D37/C37 -> 0.037398134 | E38: =E37/C37 -> 0.38782286 | F38: =F37/C37 -> 0.010856554
C39: CHI
C40: NHẬP HÀNG | D40: LƯƠNG | E40: HỖ TRỢ SHIP | F40: TRẢ HÀNG | G40: TỔNG
C41: =D33 -> 8965302 | D41: =SUM(D48:H48) -> 657275 | E41: =E33*0.065 -> 28170.87 | F41: =F54 -> 78834 | G41: =SUM(C41:F41) -> 9729581.9
C42: LỢI NHUẬN | D42: =C37-G41-F37 -> 1733364.1
C43: CHI TIẾT
C44: LƯƠNG | D44: Anh Giang | E44: A Thái | F44: Nghĩa | G44: Khánh | H44: C Hiền
D45: 250000 | E45: 64000 | F45: 184000 | G45: =24.5*950 -> 23275 | H45: 18000
C46: Hỗ trợ ship | D46: Anh Giang | E46: Anh Thái | F46: Nghĩa | G46: Khánh | H46: Nhàn
D47: 80000 | E47: 10000 | F47: 0 | G47: 0 | H47: 28000
C48: TỔNG | D48: =D45+D47 -> 330000 | E48: =E45+E47 -> 74000 | F48: =F45+F47 -> 184000 | G48: =G45+G47 -> 23275 | H48: =H45+H47 -> 46000
C49: TRẢ HÀNG | D49: Huỷ đơn | E49: Hàng hỏng | F49: Chênh lệch
D50: 53888 | E50: 16256 | F50: 8690
C53: Nội dung
C54: Tổng | F54: =SUM(D49:G53) -> 78834

Sheet 2023_7
A1: 日付 | C1: Doanh Thu | D1: Tổng Chi | E1: Ship BĐ | F1: Luỹ kế | G1: Ship | H1: Đơn
A2: 45108 | B2: 土 | C2: 495705 | D2: 96019 | E2: 37813 | F2: =C2-D2 -> 399686 | G2: 124532 | H2: 11
A3: 45109 | B3: 日 | C3: 451876 | D3: 273248 | E3: 12786 | F3: =C3-D3+F2 -> 578314 | G3: 0 | H3: 0
A4: 45110 | B4: 月 | C4: 225295 | D4: 123180 | E4: 13460 | F4: =C4-D4+F3 -> 680429 | G4: 96212 | H4: 8
A5: 45111 | B5: 火 | C5: 258091 | D5: 60945 | E5: 6214 | F5: =C5-D5+F4 -> 877575 | G5: 103472 | H5: 7
A6: 45112 | B6: 水 | C6: 354967 | D6: 1186911 | E6: 42358 | F6: =C6-D6+F5 -> 45631 | G6: 154763 | H6: 8
A7: 45113 | B7: 木 | C7: 368284 | D7: 541442 | E7: 21420 | F7: =C7-D7+F6 -> -127527 | G7: 167530 | H7: 18
A8: 45114 | B8: 金 | C8: 563589 | D8: 119045 | E8: 0 | F8: =C8-D8+F7 -> 317017 | G8: 382120 | H8: 42
A9: 45115 | B9: 土 | C9: 419912 | D9: 330941 | E9: 0 | F9: =C9-D9+F8 -> 405988 | G9: 112403 | H9: 6
A10: 45116 | B10: 日 | C10: 318644 | D10: 11525 | E10: 8743 | F10: =C10-D10+F9 -> 713107 | G10: 0 | H10: 0
A11: 45117 | B11: 月 | C11: 243441 | D11: 39330 | E11: 12768 | F11: =C11-D11+F10 -> 917218 | G11: 87650 | H11: 8
A12: 45118 | B12: 火 | C12: 491466 | D12: 148170 | E12: 36720 | F12: =C12-D12+F11 -> 1260514 | G12: 254690 | H12: 16
A13: 45119 | B13: 水 | C13: 438229 | D13: 239780 | E13: 0 | F13: =C13-D13+F12 -> 1458963 | G13: 210320 | H13: 15
A14: 45120 | B14: 木 | C14: 312439 | D14: 151536 | E14: 22102 | F14: =C14-D14+F13 -> 1619866 | G14: 186542 | H14: 12
... A32: 45138 | B32: 月 | C32: 304721 | D32: 996894 | E32: 12439 | F32: =C32-D32+F31 -> 1955807 | G32: 192320 | H32: 17
A33: TỔNG | C33: =SUM(C2:C32) -> 11780128 | D33: =SUM(D2:D32) -> 9824321 | E33: =SUM(E2:E32) -> 466556 | F33: =F32 -> 1955807 | G33: =SUM(G2:G32) -> 5015906 | H33: =SUM(H2:H32) -> 403
A34: BÁO CÁO THÁNG
C35: THU
C36: TỔNG | D36: SHIP BD | E36: SHIP | F36: THANH TOÁN POINT
C37: =C33 -> 11780128 | D37: =E33 -> 466556 | E37: =G33 -> 5015906 | F37: 93723
D38: =D37/C37 -> 0.039605342 | E38: =E37/C37 -> 0.42579385 | F38: =F37/C37 -> 0.0079560256
C39: CHI
C40: NHẬP HÀNG | D40: LƯƠNG | E40: HỖ TRỢ SHIP | F40: TRẢ HÀNG | G40: TỔNG
C41: =D33 -> 9824321 | D41: =SUM(D48:H48) -> 677500 | E41: =E33*6% -> 27993.36 | F41: =F54 -> 95672 | G41: =SUM(C41:F41) -> 10625486
C42: LỢI NHUẬN | D42: =C37-G41-F37 -> 1060918.6
C43: CHI TIẾT
C44: LƯƠNG | D44: Anh Giang | E44: A Thái | F44: Nghĩa | G44: Nhàn | H44: C Hiền
D45: 250000 | E45: 61000 | F45: 174000 | G45: 91000 | H45: 24000
C46: Hỗ trợ ship | D46: Anh Giang | E46: Anh Thái | F46: Nghĩa | G46: Nhàn | H46: C Hiền
D47: 57500 | E47: 20000 | F47: 0 | G47: 0 | H47: 0
C48: TỔNG | D48: =D45+D47 -> 307500 | E48: =E45+E47 -> 81000 | F48: =F45+F47 -> 174000 | G48: =G45+G47 -> 91000 | H48: =H45+H47 -> 24000
C49: TRẢ HÀNG | D49: Huỷ đơn | E49: Hàng hỏng | F49: Chênh lệch | G49: Thuê ship
D50: 19660 | E50: 32642 | F50: 14370 | G50: 29000
C53: Nội dung
C54: Tổng | F54: =SUM(D49:G53) -> 95672

Sheet 2023_8
A1: 日付 | C1: 売上 | D1: 支出 | E1: 入金 | F1: 不足 | G1: デリバリ | H1: 累計 | I1: 配達 | J1: 数
A2: 45139 | B2: 火 | C2: 388063 | D2: 91821 | E2: =C2-D2 -> 296242 | F2: -420 | G2: 31072 | H2: =E2+F2 -> 295822 | I2: 124532 | J2: 11
A3: 45140 | B3: 水 | C3: 224971 | D3: 350405 | E3: =C3-D3 -> -125434 | F3: -202 | G3: 0 | H3: =H2+E3+F3 -> 170186 | I3: 0 | J3: 0
A4: 45141 | B4: 木 | C4: 208043 | D4: 330427 | E4: =C4-D4 -> -122384 | F4: -108 | G4: 12412 | H4: =H3+E4+F4 -> 47694 | I4: 96212 | J4: 8
A5: 45142 | B5: 金 | C5: 602364 | D5: 355522 | E5: =C5-D5 -> 246842 | F5: -417 | G5: 26408 | H5: =H4+E5+F5 -> 294119 | I5: 103472 | J5: 7
A6: 45143 | B6: 土 | C6: 464001 | D6: 89070 | E6: =C6-D6 -> 374931 | F6: -17 | G6: 0 | H6: =H5+E6+F6 -> 669033 | I6: 154763 | J6: 8
A7: 45144 | B7: 日 | C7: 288421 | D7: 33681 | E7: =C7-D7 -> 254740 | F7: -457 | G7: 0 | H7: =H6+E7+F7 -> 923316 | I7: 167530 | J7: 18
A8: 45145 | B8: 月 | C8: 232104 | D8: 854538 | E8: =C8-D8 -> -622434 | F8: -729 | G8: 14272 | H8: =H7+E8+F8 -> 300153 | I8: 382120 | J8: 42
A9: 45146 | B9: 火 | C9: 353798 | D9: 197748 | E9: =C9-D9 -> 156050 | F9: -477 | G9: 12247 | H9: =H8+E9+F9 -> 455726 | I9: 112403 | J9: 6
A10: 45147 | B10: 水 | C10: 277820 | D10: 451545 | E10: =C10-D10 -> -173725 | F10: -327 | G10: 0 | H10: =H9+E10+F10 -> 281674 | I10: 0 | J10: 0
A11: 45148 | B11: 木 | C11: 516600 | D11: 315292 | E11: =C11-D11 -> 201308 | F11: -410 | G11: 24720 | H11: =H10+E11+F11 -> 482572 | I11: 87650 | J11: 8
A12: 45149 | B12: 金 | C12: 889181 | D12: 215562 | E12: =C12-D12 -> 673619 | F12: -472 | G12: 10722 | H12: =H11+E12+F12 -> 1155719 | I12: 254690 | J12: 16
A13: 45150 | B13: 土 | C13: 783523 | D13: 224503 | E13: =C13-D13 -> 559020 | F13: -311 | G13: 37489 | H13: =H12+E13+F13 -> 1714428 | I13: 210320 | J13: 15
A14: 45151 | B14: 日 | C14: 370475 | D14: 365034 | E14: =C14-D14 -> 5441 | F14: -774 | G14: 0 | H14: =H13+E14+F14 -> 1719095 | I14: 186542 | J14: 12
... A32: 45169 | B32: 木 | C32: 357172 | D32: 329850 | E32: =C32-D32 -> 27322 | F32: -9 | G32: 47720 | H32: =H31+E32+F32 -> 1597669 | I32: 192320 | J32: 17
A33: TỔNG | C33: =SUM(C2:C32) -> 12758842 | D33: =SUM(D2:D32) -> 11155239 | E33: =SUM(E2:E32) -> 1603603 | F33: =SUM(F2:F32) -> -5934 | G33: =SUM(G2:G32) -> 559742 | H33: =H32 -> 1597669 | I33: =SUM(I2:I32) -> 5015906 | J33: =SUM(J2:J32) -> 403
A34: BÁO CÁO THÁNG
C35: THU
C36: TỔNG | D36: SHIP BD | E36: SHIP | F36: Chênh lệch | H36: THANH TOÁN POINT
C37: =C33 -> 12758842 | D37: =G33 -> 559742 | E37: =I33 -> 5015906 | F37: =F33 -> -5934 | H37: 48431
D38: =D37/C37 -> 0.043870909 | E38: =E37/C37 -> 0.39313176 | F38: =F37/C37 -> -0.00046508923 | H38: =H37/C37 -> 0.0037958774
C39: CHI
C40: NHẬP HÀNG | D40: LƯƠNG | E40: TRẢ HÀNG | F40: Hỗ trợ ship BĐ | H40: TỔNG
C41: =D33 -> 11155239 | D41: =F48 -> 826896 | E41: =F50 -> 30444 | F41: =D37*0.065 -> 36383.23 | H41: =SUM(C41:G41) -> 12048962
C42: LỢI NHUẬN | D42: =C37-H37-H41 -> 661448.77
C43: CHI TIẾT
C44: LƯƠNG | D44: Anh Giang | E44: A Thái | F44: Nghĩa | H44: Nhàn | I44: Chị Hiền
D45: 250000 | E45: 39900 | F45: 192500 | H45: 132300 | I45: 23100
C46: Hỗ trợ ship | D46: Anh Giang | E46: A Thái | F46: Cưng | H46: Thuê ship
D47: 137896 | E47: 20000 | F47: 15200 | H47: 16000
C48: TỔNG | D48: =D45+D47 -> 387896 | E48: =E45+E47 -> 59900 | F48: =SUM(D48,E48,F45:J45,F47:J47) -> 826896
C49: TRẢ HÀNG | D49: Huỷ đơn | E49: Trả hàng | F49: TỔNG
D50: 20620 | E50: 9824 | F50: =SUM(D50:E50) -> 30444

Sheet 2023_9
A1: 日付 | C1: 売上 | D1: 支出 | E1: 入金 | F1: 不足 | G1: デリバリ | H1: 累計 | I1: BÁO CÁO THÁNG
A2: 45170 | B2: 金 | C2: 789961 | D2: 385993 | E2: =C2-D2 -> 403968 | F2: -1277 | G2: 42107 | H2: =E2+F2 -> 402691 | I2: THU
A3: 45171 | B3: 土 | C3: 721899 | D3: 127640 | E3: =C3-D3 -> 594259 | F3: -732 | G3: 21272 | H3: =H2+E3+F3 -> 996218 | I3: TỔNG | J3: SHIP BD | K3: SHIP | L3: Chênh lệch | M3: THANH TOÁN POINT
A4: 45172 | B4: 日 | C4: 485112 | D4: 297015 | E4: =C4-D4 -> 188097 | F4: 0 | G4: 0 | H4: =H3+E4+F4 -> 1184315 | I4: =C33 -> 13789456 | J4: =G33 -> 411948 | L4: =F33 -> -4407 | M4: 25586
A5: 45173 | B5: 月 | C5: 177354 | D5: 52514 | E5: =C5-D5 -> 124840 | F5: 0 | G5: 0 | H5: =H4+E5+F5 -> 1309155 | J5: =J4/I4 -> 0.02987413 | K5: =K4/I4 -> 0 | L5: =L4/I4 -> -0.00031959201 | M5: =M4/I4 -> 0.0018554757
A6: 45174 | B6: 火 | C6: 321907 | D6: 964213 | E6: =C6-D6 -> -642306 | F6: 0 | G6: 0 | H6: =H5+E6+F6 -> 666849 | I6: CHI
A7: 45175 | B7: 水 | C7: 320086 | D7: 185957 | E7: =C7-D7 -> 134129 | F7: 0 | G7: 0 | H7: =H6+E7+F7 -> 800978 | I7: NHẬP HÀNG | J7: LƯƠNG | K7: TRẢ HÀNG | L7: Hỗ trợ ship BĐ | M7: TỔNG
A8: 45176 | B8: 木 | C8: 281528 | D8: 501081 | E8: =C8-D8 -> -219553 | F8: -270 | G8: 14720 | H8: =H7+E8+F8 -> 581155 | I8: =D33 -> 11249226 | J8: =L16 -> 799650 | K8: =N19 -> 87407 | L8: =J4*0.065 -> 26776.62 | M8: =SUM(I8:L8) -> 12163060
A9: 45177 | B9: 金 | C9: 687907 | D9: 434680 | E9: =C9-D9 -> 253227 | F9: -14 | G9: 0 | H9: =H8+E9+F9 -> 834368 | I9: LỢI NHUẬN | J9: =I4-M8-M4 -> 1600810.4
A10: 45178 | B10: 土 | C10: 607769 | D10: 384991 | E10: =C10-D10 -> 222778 | F10: 10 | G10: 0 | H10: =H9+E10+F10 -> 1057156 | I10: CHI TIẾT
A11: 45179 | B11: 日 | C11: 376721 | D11: 343770 | E11: =C11-D11 -> 32951 | F11: 0 | G11: 0 | H11: =H10+E11+F11 -> 1090107 | I11: LƯƠNG - 給与
A12: 45180 | B12: 月 | C12: 241765 | D12: 573298 | E12: =C12-D12 -> -331533 | F12: 0 | G12: 18272 | H12: =H11+E12+F12 -> 758574 | I12: A. Giang | J12: A.Thái | K12: C.Hiền | L12: Nhàn | M12: Cưng | N12: Nghĩa
A13: 45181 | B13: 火 | C13: 291238 | D13: 104554 | E13: =C13-D13 -> 186684 | F13: 0 | G13: 37911 | H13: =H12+E13+F13 -> 945258 | I13: 250000 | J13: 75075 | K13: 19425 | L13: 119700 | M13: 33250 | N13: 194000
A14: 45182 | B14: 水 | C14: 413434 | D14: 637495 | E14: =C14-D14 -> -224061 | F14: -122 | G14: 0 | H14: =H13+E14+F14 -> 721075 | I14: HỖ TRỢ
A15: 45183 | B15: 木 | C15: 354850 | D15: 369372 | E15: =C15-D15 -> -14522 | F15: 2 | G15: 0 | H15: =H14+E15+F15 -> 706555 | I15: 88200 | J15: 20000
A16: 45184 | B16: 金 | C16: 715090 | D16: 281814 | E16: =C16-D16 -> 433276 | F16: 0 | G16: 0 | H16: =H15+E16+F16 -> 1139831 | I16: TỔNG | L16: =SUM(I13:N13)+SUM(I15:N15) -> 799650
A17: 45185 | B17: 土 | C17: 637018 | D17: 711233 | E17: =C17-D17 -> -74215 | F17: -18 | G17: 27120 | H17: =H16+E17+F17 -> 1065598 | I17: CHI KHÁC - その他
A18: 45186 | B18: 日 | C18: 365865 | D18: 249769 | E18: =C18-D18 -> 116096 | F18: -27 | G18: 0 | H18: =H17+E18+F18 -> 1181667 | I18: TRẢ - HUỶ | J18: 社会保険 | K18: CHÊNH LỆCH | L18: XĂNG XE | M18: THUÊ XE | N18: TỔNG
A19: 45187 | B19: 月 | C19: 334806 | D19: 165855 | E19: =C19-D19 -> 168951 | F19: -430 | G19: 12721 | H19: =H18+E19+F19 -> 1350188 | I19: 30000 | J19: 35000 | K19: 4407 | L19: 13000 | M19: 5000 | N19: =SUM(I19:M19) -> 87407
A20: 45188 | B20: 火 | C20: 268795 | D20: 183887 | E20: =C20-D20 -> 84908 | F20: 0 | G20: 19997 | H20: =H19+E20+F20 -> 1435096
A21: 45189 | B21: 水 | C21: 256197 | D21: 313486 | E21: =C21-D21 -> -57289 | F21: 0 | G21: 5762 | H21: =H20+E21+F21 -> 1377807
A22: 45190 | B22: 木 | C22: 239216 | D22: 361664 | E22: =C22-D22 -> -122448 | F22: -112 | G22: 14720 | H22: =H21+E22+F22 -> 1255247
A23: 45191 | B23: 金 | C23: 653657 | D23: 191131 | E23: =C23-D23 -> 462526 | F23: -224 | G23: 43020 | H23: =H22+E23+F23 -> 1717549
A24: 45192 | B24: 土 | C24: 676152 | D24: 76760 | E24: =C24-D24 -> 599392 | F24: 0 | G24: 31493 | H24: =H23+E24+F24 -> 2316941
A25: 45193 | B25: 日 | C25: 318815 | D25: 768020 | E25: =C25-D25 -> -449205 | F25: 0 | G25: 0 | H25: =H24+E25+F25 -> 1867736
A26: 45194 | B26: 月 | C26: 388724 | D26: 789950 | E26: =C26-D26 -> -401226 | F26: 0 | G26: 22780 | H26: =H25+E26+F26 -> 1466510
A27: 45195 | B27: 火 | C27: 459864 | D27: 395937 | E27: =C27-D27 -> 63927 | F27: 0 | G27: 0 | H27: =H26+E27+F27 -> 1530437
A28: 45196 | B28: 水 | C28: 478328 | D28: 305761 | E28: =C28-D28 -> 172567 | F28: -472 | G28: 37420 | H28: =H27+E28+F28 -> 1702532
A29: 45197 | B29: 木 | C29: 443547 | D29: 273404 | E29: =C29-D29 -> 170143 | F29: 0 | G29: 21212 | H29: =H28+E29+F29 -> 1872675
A30: 45198 | B30: 金 | C30: 674894 | D30: 291926 | E30: =C30-D30 -> 382968 | F30: 0 | G30: 0 | H30: =H29+E30+F30 -> 2255643
A31: 45199 | B31: 土 | C31: 806957 | D31: 526056 | E31: =C31-D31 -> 280901 | F31: -721 | G31: 41421 | H31: =H30+E31+F31 -> 2535823
E32: =C32-D32 -> 0 | H32: =H31+E32+F32 -> 2535823
A33: TỔNG | C33: =SUM(C2:C32) -> 13789456 | D33: =SUM(D2:D32) -> 11249226 | E33: =SUM(E2:E32) -> 2540230 | F33: =SUM(F2:F32) -> -4407 | G33: =SUM(G2:G32) -> 411948 | H33: =H32 -> 2535823

Sheet 2023_10
A1: 日付 | C1: 売上 | D1: 支出 | E1: 入金 | F1: 不足 | G1: デリバリ | H1: 累計 | I1: BÁO CÁO THÁNG
A2: 45200 | B2: 日 | C2: 439404 | D2: 97531 | E2: =C2-D2 -> 341873 | F2: 0 | G2: 24302 | H2: =E2+F2 -> 341873 | I2: THU
A3: 45201 | B3: 月 | C3: 293024 | D3: 193295 | E3: =C3-D3 -> 99729 | F3: 0 | G3: 0 | H3: =H2+E3+F3 -> 441602 | I3: TỔNG | J3: SHIP BD | K3: SHIP | L3: Chênh lệch | M3: THANH TOÁN POINT
A4: 45202 | B4: 火 | C4: 356376 | D4: 1153287 | E4: =C4-D4 -> -796911 | F4: -17 | G4: 12712 | H4: =H3+E4+F4 -> -355326 | I4: =C33 -> 12689656 | J4: =G33 -> 339621 | L4: =F33 -> -3598 | M4: 12094
A5: 45203 | B5: 水 | C5: 202909 | D5: 644555 | E5: =C5-D5 -> -441646 | F5: -340 | G5: 9780 | H5: =H4+E5+F5 -> -797312 | J5: =J4/I4 -> 0.02676361 | K5: =K4/I4 -> 0 | L5: =L4/I4 -> -0.00028353802 | M5: =M4/I4 -> 0.00095305972
A6: 45204 | B6: 木 | C6: 333146 | D6: 144531 | E6: =C6-D6 -> 188615 | F6: 0 | G6: 0 | H6: =H5+E6+F6 -> -608697 | I6: CHI
A7: 45205 | B7: 金 | C7: 754186 | D7: 341290 | E7: =C7-D7 -> 412896 | F7: 0 | G7: 0 | H7: =H6+E7+F7 -> -195801 | I7: NHẬP HÀNG | J7: LƯƠNG | K7: TRẢ HÀNG | L7: Hỗ trợ ship BĐ | M7: TỔNG
A8: 45206 | B8: 土 | C8: 815492 | D8: 510750 | E8: =C8-D8 -> 304742 | F8: 22 | G8: 60271 | H8: =H7+E8+F8 -> 108963 | I8: =D33 -> 11138899 | J8: =L16 -> 747750 | K8: =N19 -> 84657 | L8: =J4*0.065 -> 22075.365 | M8: =SUM(I8:L8) -> 11993381
A9: 45207 | B9: 日 | C9: 331185 | D9: 80902 | E9: =C9-D9 -> 250283 | F9: -470 | G9: 0 | H9: =H8+E9+F9 -> 358776 | I9: LỢI NHUẬN | J9: =I4-M8-M4 -> 684180.63
A10: 45208 | B10: 月 | C10: 292673 | D10: 253143 | E10: =C10-D10 -> 39530 | F10: 0 | G10: 21120 | H10: =H9+E10+F10 -> 398306 | I10: CHI TIẾT
A11: 45209 | B11: 火 | C11: 294338 | D11: 1004156 | E11: =C11-D11 -> -709818 | F11: 0 | G11: 0 | H11: =H10+E11+F11 -> -311512 | I11: LƯƠNG - 給与
A12: 45210 | B12: 水 | C12: 331533 | D12: 410522 | E12: =C12-D12 -> -78989 | F12: 2 | G12: 22727 | H12: =H11+E12+F12 -> -390499 | I12: A. Giang | J12: A.Thái | K12: C.Hiền | L12: Nhàn | M12: Cưng | N12: Nghĩa
A13: 45211 | B13: 木 | C13: 280023 | D13: 267327 | E13: =C13-D13 -> 12696 | F13: -6 | G13: 11011 | H13: =H12+E13+F13 -> -377809 | I13: 250000 | J13: 180000 | K13: 60500 | L13: 16000 | M13: 34250 | N13: 185000
A14: 45212 | B14: 金 | C14: 595580 | D14: 312102 | E14: =C14-D14 -> 283478 | F14: 157 | G14: 0 | H14: =H13+E14+F14 -> -94174 | I14: HỖ TRỢ
A15: 45213 | B15: 土 | C15: 776798 | D15: 512510 | E15: =C15-D15 -> 264288 | F15: -420 | G15: 0 | H15: =H14+E15+F15 -> 169694 | I15: 22000
A16: 45214 | B16: 日 | C16: 374422 | D16: 44310 | E16: =C16-D16 -> 330112 | F16: -221 | G16: 17720 | H16: =H15+E16+F16 -> 499585 | I16: TỔNG | L16: =SUM(I13:N13)+SUM(I15:N15) -> 747750
A17: 45215 | B17: 月 | C17: 195191 | D17: 304208 | E17: =C17-D17 -> -109017 | F17: -75 | G17: 17708 | H17: =H16+E17+F17 -> 390493 | I17: CHI KHÁC - その他
A18: 45216 | B18: 火 | C18: 293535 | D18: 502427 | E18: =C18-D18 -> -208892 | F18: 0 | G18: 0 | H18: =H17+E18+F18 -> 181601 | I18: TRẢ - HUỶ | J18: 社会保険 | K18: CHÊNH LỆCH | L18: XĂNG XE | M18: Khác | N18: TỔNG
A19: 45217 | B19: 水 | C19: 195064 | D19: 388611 | E19: =C19-D19 -> -193547 | F19: 0 | G19: 4780 | H19: =H18+E19+F19 -> -11946 | I19: 8000 | J19: 35000 | K19: 4407 | L19: 13000 | M19: =N23 -> 24250 | N19: =SUM(I19:M19) -> 84657
A20: 45218 | B20: 木 | C20: 283240 | D20: 244742 | E20: =C20-D20 -> 38498 | F20: 2 | G20: 20071 | H20: =H19+E20+F20 -> 26554
A21: 45219 | B21: 金 | C21: 592511 | D21: 369238 | E21: =C21-D21 -> 223273 | F21: -798 | G21: 0 | H21: =H20+E21+F21 -> 249029 | I21: 参考
A22: 45220 | B22: 土 | C22: 450664 | D22: 96665 | E22: =C22-D22 -> 353999 | F22: 0 | G22: 0 | H22: =H21+E22+F22 -> 603028 | I22: Anh Minh | J22: LƯƠNG | K22: ĐI LẠI | N22: TỔNG
A23: 45221 | B23: 日 | C23: 369899 | D23: 150706 | E23: =C23-D23 -> 219193 | F23: 0 | G23: 17424 | H23: =H22+E23+F23 -> 822221 | J23: 21850 | K23: 2400 | N23: =SUM(J23:M23) -> 24250
A24: 45222 | B24: 月 | C24: 209750 | D24: 98052 | E24: =C24-D24 -> 111698 | F24: -22 | G24: 0 | H24: =H23+E24+F24 -> 933897
A25: 45223 | B25: 火 | C25: 271625 | D25: 138980 | E25: =C25-D25 -> 132645 | F25: -423 | G25: 21720 | H25: =H24+E25+F25 -> 1066119
A26: 45224 | B26: 水 | C26: 378544 | D26: 1096679 | E26: =C26-D26 -> -718135 | F26: 0 | G26: 4872 | H26: =H25+E26+F26 -> 347984
A27: 45225 | B27: 木 | C27: 424075 | D27: 217761 | E27: =C27-D27 -> 206314 | F27: 0 | G27: 0 | H27: =H26+E27+F27 -> 554298
A28: 45226 | B28: 金 | C28: 693142 | D28: 384833 | E28: =C28-D28 -> 308309 | F28: -221 | G28: 34217 | H28: =H27+E28+F28 -> 862386
A29: 45227 | B29: 土 | C29: 844628 | D29: 511660 | E29: =C29-D29 -> 332968 | F29: -657 | G29: 0 | H29: =H28+E29+F29 -> 1194697
A30: 45228 | B30: 日 | C30: 380493 | D30: 39632 | E30: =C30-D30 -> 340861 | F30: 0 | G30: 18471 | H30: =H29+E30+F30 -> 1535558
A31: 45229 | B31: 月 | C31: 355739 | D31: 138624 | E31: =C31-D31 -> 217115 | F31: 0 | G31: 9841 | H31: =H30+E31+F31 -> 1752673
A32: 45230 | B32: 火 | C32: 280467 | D32: 485870 | E32: =C32-D32 -> -205403 | F32: -111 | G32: 10874 | H32: =H31+E32+F32 -> 1547159
A33: TỔNG | C33: =SUM(C2:C32) -> 12689656 | D33: =SUM(D2:D32) -> 11138899 | E33: =SUM(E2:E32) -> 1550757 | F33: =SUM(F2:F32) -> -3598 | G33: =SUM(G2:G32) -> 339621 | H33: =H32 -> 1547159

Sheet Chi tiết_2023_1１
A1: CHI | B1: CHI TIẾT | C1: MỤC | F1: TỔNG THEO MỤC
A2: 45231 | F2: 食材 | G2: =SUMIF($C$3:$C$497,"=食材",$A$3:$A$497) -> 7882672 | H2: =SUM(G2:G10) -> 11196218
A3: 18650 | B3: Hành tím | C3: 食材 | F3: 消耗品 | G3: =SUMIF($C$3:$C$497,"=消耗品",$A$3:$A$497) -> 54827
A4: 88020 | B4: Gà | C4: 食材 | F4: 家賃 | G4: =SUMIF($C$3:$C$497,"=家賃",$A$3:$A$497) -> 132000
A5: 484215 | B5: Thịt | C5: 食材 | F5: 水代 | G5: =SUMIF($C$3:$C$497,"=水代",$A$3:$A$497) -> 0
A6: 26155 | B6: Bắp heo rút xương | C6: 食材 | F6: 電気代 | G6: =SUMIF($C$3:$C$497,"=電気代",$A$3:$A$497) -> 67185
A7: 10400 | B7: Sả tươi | C7: 食材 | F7: ガソリン | G7: =SUMIF($C$3:$C$497,"=ガソリン",$A$3:$A$497) -> 68588
A8: 59346 | B8: Kome | C8: 食材 | F8: 米 | G8: =SUMIF($C$3:$C$497,"=米",$A$3:$A$497) -> 693600
A9: =SUM(A3:A8) -> 686786 | F9: TPX | G9: =SUMIF($C$3:$C$497,"=TPX",$A$3:$A$497) -> 2101650
A10: 45232 | F10: その他 | G10: =SUMIF($C$3:$C$497,"=その他",$A$3:$A$497) -> 195696
A11: 2510 | B11: Phí ship | C11: その他
A12: 110 | B12: Túi bóng | C12: 消耗品
A13: 8836 | B13: Xăng | C13: ガソリン
A14: 82582 | B14: Ba chỉ | C14: 食材
A15: 15840 | B15: Hành tím | C15: 食材
A16: 45600 | B16: Rau | C16: 食材
A17: 62550 | B17: Kome | C17: 食材
A18: =SUM(A11:A17) -> 218028
A19: 45233
A20: 160 | B20: Phí qua hầm | C20: その他
A21: 2000 | B21: Túi rác | C21: 消耗品
A22: 200440 | B22: Thuốc lá | C22: 食材
A23: 2754 | B23: Túi bóng | C23: 消耗品
A24: 27328 | B24: Xoài | C24: 食材
A25: 4900 | B25: Chuối xanh | C25: 食材
A26: 6182 | B26: Túi bóng | C26: 消耗品
A27: 366430 | B27: Chè đông lạnh | C27: 食材
A28: 25072 | B28: Sữa Milo | C28: 食材
A29: 47670 | B29: Nam ngư | C29: 食材
A30: 25996 | B30: Tai heo | C30: 食材
A31: 73750 | B31: Hoa chuối | C31: 食材
... A33: 80000 | B33: Gạo | C33: 米
A34: =SUM(A20:A33) -> 886582
A35: 45234
A36: 2510 | B36: Phí ship | C36: その他
A37: 3350 | B37: Sả + ớt | C37: 食材
A38: 42000 | B38: Bún safoco | C38: 食材
A39: 32462 | B39: G7 | C39: 食材
A40: 18400 | B40: Phở gà | C40: 食材
A41: =SUM(A36:A40) -> 98722
...

Sheet 2023_11
A1: 日付 | C1: 売上 | D1: 支出 | E1: 入金 | F1: 不足 | G1: デリバリ | H1: 累計 | I1: BÁO CÁO THÁNG
A2: 45231 | B2: 水 | C2: 389338 | D2: 686786 | E2: =C2-D2 -> -297448 | F2: -2 | G2: 12547 | H2: =E2+F2 -> -297450 | I2: THU
A3: 45232 | B3: 木 | C3: 204632 | D3: 218028 | E3: =C3-D3 -> -13396 | F3: -17 | G3: 0 | H3: =H2+E3+F3 -> -310863 | I3: TỔNG | J3: SHIP BD | K3: SHIP | L3: Chênh lệch | M3: THANH TOÁN POINT
A4: 45233 | B4: 金 | C4: 861190 | D4: 886582 | E4: =C4-D4 -> -25392 | F4: 0 | G4: 45541 | H4: =H3+E4+F4 -> -336255 | I4: =C33 -> 12007335 | J4: =G33 -> 270102 | L4: =F33 -> -1378 | M4: 19881
A5: 45234 | B5: 土 | C5: 401924 | D5: 98722 | E5: =C5-D5 -> 303202 | F5: 0 | G5: 8571 | H5: =H4+E5+F5 -> -33053 | J5: =J4/I4 -> 0.02249475 | K5: =K4/I4 -> 0 | L5: =L4/I4 -> -0.00011476318 | M5: =M4/I4 -> 0.0016557379
A6: 45235 | B6: 日 | C6: 391274 | D6: 762026 | E6: =C6-D6 -> -370752 | F6: 0 | G6: 0 | H6: =H5+E6+F6 -> -403805 | I6: CHI
A7: 45236 | B7: 月 | C7: 180736 | D7: 378980 | E7: =C7-D7 -> -198244 | F7: -22 | G7: 0 | H7: =H6+E7+F7 -> -602071 | I7: NHẬP HÀNG | J7: LƯƠNG | K7: CHI KHÁC | L7: Hỗ trợ ship BĐ | M7: TỔNG
A8: 45237 | B8: 火 | C8: 315166 | D8: 47211 | E8: =C8-D8 -> 267955 | F8: -29 | G8: 12475 | H8: =H7+E8+F8 -> -334145 | I8: =D33 -> 11196218 | J8: =L16 -> 705000 | K8: =N19 -> 55542 | L8: =J4*0.065 -> 17556.63 | M8: =SUM(I8:L8) -> 11974317
A9: 45238 | B9: 水 | C9: 186466 | D9: 640942 | E9: =C9-D9 -> -454476 | F9: 24 | G9: 0 | H9: =H8+E9+F9 -> -788597 | I9: LỢI NHUẬN | J9: =I4-M8-M4 -> 13137.37
A10: 45239 | B10: 木 | C10: 315770 | D10: 193448 | E10: =C10-D10 -> 122322 | F10: -222 | G10: 0 | H10: =H9+E10+F10 -> -666497 | I10: CHI TIẾT
A11: 45240 | B11: 金 | C11: 635625 | D11: 164203 | E11: =C11-D11 -> 471422 | F11: 0 | G11: 11254 | H11: =H10+E11+F11 -> -195075 | I11: LƯƠNG - 給与
A12: 45241 | B12: 土 | C12: 987759 | D12: 202771 | E12: =C12-D12 -> 784988 | F12: 0 | G12: 24710 | H12: =H11+E12+F12 -> 589913 | I12: A. Giang | J12: A.Thái | K12: C.Hiền | L12: Nhàn | M12: Cưng | N12: Nghĩa
A13: 45242 | B13: 日 | C13: 367750 | D13: 213701 | E13: =C13-D13 -> 154049 | F13: -779 | G13: 0 | H13: =H12+E13+F13 -> 743183 | I13: 250000 | J13: 68500 | K13: 75000 | L13: 10000 | M13: 35500 | N13: 197000
A14: 45243 | B14: 月 | C14: 268983 | D14: 1311196 | E14: =C14-D14 -> -1042213 | F14: 22 | G14: 0 | H14: =H13+E14+F14 -> -299008 | I14: HỖ TRỢ
A15: 45244 | B15: 火 | C15: 372138 | D15: 275915 | E15: =C15-D15 -> 96223 | F15: -54 | G15: 15442 | H15: =H14+E15+F15 -> -202839 | I15: 69000
A16: 45245 | B16: 水 | C16: 272372 | D16: 313598 | E16: =C16-D16 -> -41226 | F16: -11 | G16: 0 | H16: =H15+E16+F16 -> -244076 | I16: TỔNG | L16: =SUM(I13:N13)+SUM(I15:N15) -> 705000
A17: 45246 | B17: 木 | C17: 243354 | D17: 247550 | E17: =C17-D17 -> -4196 | F17: 0 | G17: 8521 | H17: =H16+E17+F17 -> -248272 | I17: CHI KHÁC - その他
A18: 45247 | B18: 金 | C18: 605936 | D18: 103641 | E18: =C18-D18 -> 502295 | F18: 124 | G18: 12545 | H18: =H17+E18+F18 -> 254147 | I18: TRẢ - HUỶ | J18: 社会保険 | K18: CHÊNH LỆCH | L18: XĂNG XE | M18: Khác | N18: TỔNG
A19: 45248 | B19: 土 | C19: 534465 | D19: 256569 | E19: =C19-D19 -> 277896 | F19: 11 | G19: 0 | H19: =H18+E19+F19 -> 532054 | I19: 18000 | J19: 35000 | M19: =N23 -> 2542 | N19: =SUM(I19:M19) -> 55542
A20: 45249 | B20: 日 | C20: 234365 | D20: 402138 | E20: =C20-D20 -> -167773 | F20: -22 | G20: 0 | H20: =H19+E20+F20 -> 364259
A21: 45250 | B21: 月 | C21: 258659 | D21: 81200 | E21: =C21-D21 -> 177459 | F21: -41 | G21: 15754 | H21: =H20+E21+F21 -> 541677 | I21: 参考
A22: 45251 | B22: 火 | C22: 266581 | D22: 40190 | E22: =C22-D22 -> 226391 | F22: 0 | G22: 12272 | H22: =H21+E22+F22 -> 768068 | J22: Giảm giá HD | N22: TỔNG
A23: 45252 | B23: 水 | C23: 359856 | D23: 165370 | E23: =C23-D23 -> 194486 | F23: -254 | G23: 0 | H23: =H22+E23+F23 -> 962300 | J23: 2542 | N23: =SUM(J23:M23) -> 2542
A24: 45253 | B24: 木 | C24: 332407 | D24: 611083 | E24: =C24-D24 -> -278676 | F24: 0 | G24: 0 | H24: =H23+E24+F24 -> 683624
A25: 45254 | B25: 金 | C25: 679449 | D25: 186047 | E25: =C25-D25 -> 493402 | F25: -4 | G25: 0 | H25: =H24+E25+F25 -> 1177022
A26: 45255 | B26: 土 | C26: 736726 | D26: 272342 | E26: =C26-D26 -> 464384 | F26: 0 | G26: 15756 | H26: =H25+E26+F26 -> 1641406
A27: 45256 | B27: 日 | C27: 509454 | D27: 305588 | E27: =C27-D27 -> 203866 | F27: -125 | G27: 48510 | H27: =H26+E27+F27 -> 1845147
A28: 45257 | B28: 月 | C28: 328560 | D28: 1019462 | E28: =C28-D28 -> -690902 | F28: 12 | G28: 0 | H28: =H27+E28+F28 -> 1154257
A29: 45258 | B29: 火 | C29: 155170 | D29: 416397 | E29: =C29-D29 -> -261227 | F29: 0 | G29: 0 | H29: =H28+E29+F29 -> 893030
A30: 45259 | B30: 水 | C30: 370378 | D30: 443466 | E30: =C30-D30 -> -73088 | F30: 0 | G30: 15750 | H30: =H29+E30+F30 -> 819942
A31: 45260 | B31: 木 | C31: 240852 | D31: 251066 | E31: =C31-D31 -> -10214 | F31: 11 | G31: 10454 | H31: =H30+E31+F31 -> 809739
A32: 0/12/2023 | B32: 金 | C32: 0 | D32: 0 | E32: =C32-D32 -> 0 | H32: =H31+E32+F32 -> 809739
A33: TỔNG | C33: =SUM(C2:C32) -> 12007335 | D33: =SUM(D2:D32) -> 11196218 | E33: =SUM(E2:E32) -> 811117 | F33: =SUM(F2:F32) -> -1378 | G33: =SUM(G2:G32) -> 270102 | H33: =H32 -> 809739

Sheet Chi tiết_2023_12
A1: CHI | B1: CHI TIẾT | C1: MỤC | E1: TỔNG THEO MỤC
A2: 45261 | E2: 食材 | F2: =SUMIF($C$3:$C$193,"=食材",$A$3:$A$193) -> 1079483 | G2: =SUM(F2:F8) -> 1199761
A3: 6776 | B3: Túi bóng | C3: 消耗品 | E3: 消耗品 | F3: =SUMIF($C$3:$C$193,"=消耗品",$A$3:$A$193) -> 6776
A4: 114020 | B4: Thịt | C4: 食材 | E4: 家賃 | F4: =SUMIF($C$3:$C$193,"=家賃",$A$3:$A$193) -> 0
A5: 39400 | B5: Xoài | C5: 食材 | E5: 水代 | F5: =SUMIF($C$3:$C$193,"=水代",$A$3:$A$193) -> 9242
A6: 64705 | B6: Bim bim mix | C6: 食材 | E6: 電気代 | F6: =SUMIF($C$3:$C$193,"=電気代",$A$3:$A$193) -> 0
A7: 48790 | B7: Ba chỉ | C7: 食材 | E7: 米 | F7: =SUMIF($C$3:$C$193,"=米",$A$3:$A$193) -> 102500
A8: =SUM(A3:A7) -> 273691 | E8: その他 | F8: =SUMIF($C$3:$C$193,"=その他",$A$3:$A$193) -> 1760
A9: 45262
A10: 520 | B10: Cao tốc | C10: その他
A11: 320 | B11: Phí qua hầm | C11: その他
A12: 9242 | B12: Tiền nước tháng 9 | C12: 水代
A13: 50401 | B13: Bún safoco | C13: 食材
A14: 53740 | B14: Sả tươi + Number | C14: 食材
A15: 41980 | B15: Kome | C15: 食材
A16: 59904 | B16: Vịt đông lạnh | C16: 食材
A17: 102500 | B17: Gạo | C17: 米
A18: =SUM(A10:A17) -> 318607
A19: 45263
A20: 141440 | B20: Thuốc lá | C20: 食材
A21: 400 | B21: Bãi xe | C21: その他
A22: 36330 | B22: Chè đông lạnh | C22: 食材
A23: 55900 | B23: Mướp | C23: 食材
A24: 26440 | B24: Pía mini | C24: 食材
A25: 4900 | B25: Chuối xanh | C25: 食材
A26: 35220 | B26: Sữa TH socola | C26: 食材
A27: 123560 | B27: Thịt | C27: 食材
A28: 43412 | B28: Thịt | C28: 食材
A29: =SUM(A20:A28) -> 467602
A30: 45264
A31: 14780 | B31: Chân gà | C31: 食材
A32: 520 | B32: Cao tốc | C32: その他
A33: 27862 | B33: Tai heo | C33: 食材
A34: 20729 | B34: Mì chính | C34: 食材
A35: 75970 | B35: Ba chỉ | C35: 食材
A36: =SUM(A31:A35) -> 139861

Sheet 2023_12
A1: 日付 | C1: 売上 | D1: 支出 | E1: 入金 | F1: 不足 | G1: デリバリ | H1: 累計 | I1: BÁO CÁO THÁNG
A2: 45261 | B2: 金 | C2: 738781 | D2: 273691 | E2: =C2-D2 -> 465090 | F2: 0 | G2: 34521 | H2: =E2+F2 -> 465090 | I2: THU
A3: 45262 | B3: 土 | C3: 595882 | D3: 318607 | E3: =C3-D3 -> 277275 | F3: 0 | G3: 0 | H3: =H2+E3+F3 -> 742365 | I3: TỔNG | J3: SHIP BD | K3: SHIP | L3: Chênh lệch | M3: THANH TOÁN POINT
A4: 45263 | B4: 日 | C4: 402381 | D4: 467602 | E4: =C4-D4 -> -65221 | F4: -27 | G4: 0 | H4: =H3+E4+F4 -> 677117 | I4: =C33 -> 15504613 | J4: =G33 -> 318236 | L4: =F33 -> -2561 | M4: 17416
A5: 45264 | B5: 月 | C5: 256488 | D5: 139861 | E5: =C5-D5 -> 116627 | F5: 0 | G5: 12332 | H5: =H4+E5+F5 -> 793744 | J5: =J4/I4 -> 0.020525246 | K5: =K4/I4 -> 0 | L5: =L4/I4 -> -0.00016517665 | M5: =M4/I4 -> 0.0011232786
A6: 45265 | B6: 火 | C6: 352259 | D6: 457508 | E6: =C6-D6 -> -105249 | F6: -452 | G6: 0 | H6: =H5+E6+F6 -> 688043 | I6: CHI
A7: 45266 | B7: 水 | C7: 279923 | D7: 421325 | E7: =C7-D7 -> -141402 | F7: 0 | G7: 0 | H7: =H6+E7+F7 -> 546641 | I7: NHẬP HÀNG | J7: LƯƠNG | K7: TRẢ HÀNG | L7: Hỗ trợ ship BĐ | M7: TỔNG
A8: 45267 | B8: 木 | C8: 300658 | D8: 173080 | E8: =C8-D8 -> 127578 | F8: 0 | G8: 22312 | H8: =H7+E8+F8 -> 674219 | I8: =D33 -> 13711257 | J8: =L16 -> 794500 | K8: =N19 -> 60744 | L8: =J4*0.065 -> 20685.34 | M8: =SUM(I8:L8) -> 14587186
A9: 45268 | B9: 金 | C9: 588630 | D9: 280309 | E9: =C9-D9 -> 308321 | F9: 0 | G9: 0 | H9: =H8+E9+F9 -> 982540 | I9: LỢI NHUẬN | J9: =I4-M8-M4 -> 900010.66
A10: 45269 | B10: 土 | C10: 840506 | D10: 338435 | E10: =C10-D10 -> 502071 | F10: 21 | G10: 9753 | H10: =H9+E10+F10 -> 1484632 | I10: CHI TIẾT
A11: 45270 | B11: 日 | C11: 336089 | D11: 661617 | E11: =C11-D11 -> -325528 | F11: -43 | G11: 0 | H11: =H10+E11+F11 -> 1159061 | I11: LƯƠNG - 給与
A12: 45271 | B12: 月 | C12: 179290 | D12: 204034 | E12: =C12-D12 -> -24744 | F12: -12 | G12: 12210 | H12: =H11+E12+F12 -> 1134305 | I12: A. Giang | J12: A.Thái | K12: C.Hiền | L12: Nhàn | M12: Cưng | N12: Nghĩa
A13: 45272 | B13: 火 | C13: 455506 | D13: 802449 | E13: =C13-D13 -> -346943 | F13: 0 | G13: 22431 | H13: =H12+E13+F13 -> 787362 | I13: 250000 | J13: 90000 | K13: 100500 | L13: 0 | M13: 39000 | N13: 220000
A14: 45273 | B14: 水 | C14: 245075 | D14: 607037 | E14: =C14-D14 -> -361962 | F14: 0 | G14: 0 | H14: =H13+E14+F14 -> 425400 | I14: HỖ TRỢ
A15: 45274 | B15: 木 | C15: 283889 | D15: 51817 | E15: =C15-D15 -> 232072 | F15: -14 | G15: 0 | H15: =H14+E15+F15 -> 657458 | I15: 95000
A16: 45275 | B16: 金 | C16: 680907 | D16: 419811 | E16: =C16-D16 -> 261096 | F16: 23 | G16: 65763 | H16: =H15+E16+F16 -> 918577 | I16: TỔNG | L16: =SUM(I13:N13)+SUM(I15:N15) -> 794500
A17: 45276 | B17: 土 | C17: 539452 | D17: 223226 | E17: =C17-D17 -> 316226 | F17: -654 | G17: 0 | H17: =H16+E17+F17 -> 1234149 | I17: CHI KHÁC - その他
A18: 45277 | B18: 日 | C18: 316433 | D18: 223410 | E18: =C18-D18 -> 93023 | F18: -87 | G18: 12650 | H18: =H17+E18+F18 -> 1327085 | I18: TRẢ - HUỶ | J18: 社会保険 | K18: CHÊNH LỆCH | L18: XĂNG XE | M18: Khác | N18: TỔNG
A19: 45278 | B19: 月 | C19: 149668 | D19: 319156 | E19: =C19-D19 -> -169488 | F19: 0 | G19: 0 | H19: =H18+E19+F19 -> 1157597 | I19: 21781 | J19: 35000 | M19: =N23 -> 3963 | N19: =SUM(I19:M19) -> 60744
A20: 45279 | B20: 火 | C20: 306776 | D20: 244490 | E20: =C20-D20 -> 62286 | F20: 0 | G20: 11432 | H20: =H19+E20+F20 -> 1219883
A21: 45280 | B21: 水 | C21: 273501 | D21: 654779 | E21: =C21-D21 -> -381278 | F21: -144 | G21: 0 | H21: =H20+E21+F21 -> 838461 | I21: 参考
A22: 45281 | B22: 木 | C22: 335730 | D22: 576774 | E22: =C22-D22 -> -241044 | F22: 0 | G22: 15310 | H22: =H21+E22+F22 -> 597417 | J22: Giảm giá HD | N22: TỔNG
A23: 45282 | B23: 金 | C23: 729693 | D23: 30852 | E23: =C23-D23 -> 698841 | F23: -122 | G23: 0 | H23: =H22+E23+F23 -> 1296136 | J23: 3963 | N23: =SUM(J23:M23) -> 3963
A24: 45283 | B24: 土 | C24: 639922 | D24: 246060 | E24: =C24-D24 -> 393862 | F24: 0 | G24: 12101 | H24: =H23+E24+F24 -> 1689998
A25: 45284 | B25: 日 | C25: 431463 | D25: 220777 | E25: =C25-D25 -> 210686 | F25: 21 | G25: 0 | H25: =H24+E25+F25 -> 1900705
A26: 45285 | B26: 月 | C26: 438061 | D26: 296070 | E26: =C26-D26 -> 141991 | F26: -12 | G26: 43521 | H26: =H25+E26+F26 -> 2042684
A27: 45286 | B27: 火 | C27: 660026 | D27: 414022 | E27: =C27-D27 -> 246004 | F27: -33 | G27: 12329 | H27: =H26+E27+F27 -> 2288655
A28: 45287 | B28: 水 | C28: 575883 | D28: 794590 | E28: =C28-D28 -> -218707 | F28: 12 | G28: 0 | H28: =H27+E28+F28 -> 2069960
A29: 45288 | B29: 木 | C29: 607217 | D29: 317276 | E29: =C29-D29 -> 289941 | F29: -231 | G29: 0 | H29: =H28+E29+F29 -> 2359670
A30: 45289 | B30: 金 | C30: 1262317 | D30: 832331 | E30: =C30-D30 -> 429986 | F30: 0 | G30: 12451 | H30: =H29+E30+F30 -> 2789656
A31: 45290 | B31: 土 | C31: 1335501 | D31: 306462 | E31: =C31-D31 -> 1029039 | F31: -453 | G31: 0 | H31: =H30+E31+F31 -> 3818242
A32: 45291 | B32: 日 | C32: 366706 | D32: 2393799 | E32: =C32-D32 -> -2027093 | F32: -354 | G32: 19120 | H32: =H31+E32+F32 -> 1790795
A33: TỔNG | C33: =SUM(C2:C32) -> 15504613 | D33: =SUM(D2:D32) -> 13711257 | E33: =SUM(E2:E32) -> 1793356 | F33: =SUM(F2:F32) -> -2561 | G33: =SUM(G2:G32) -> 318236 | H33: =H32 -> 1790795

Sheet 2024_1
A1: 日付 | C1: 売上 | D1: 支出 | E1: 入金 | F1: 不足 | G1: デリバリ | H1: 累計 | I1: BÁO CÁO THÁNG 1/2024
A2: 45292 | B2: 月 | C2: 363702 | D2: 374578 | E2: =C2-D2 -> -10876 | F2: -451 | G2: 12574 | H2: =E2+F2 -> -11327 | I2: THU
A3: 45262 | B3: 火 | C3: 333568 | D3: 75050 | E3: =C3-D3 -> 258518 | F3: 0 | G3: 22741 | H3: =H2+E3+F3 -> 247191 | I3: TỔNG | J3: SHIP BD | K3: SHIP | L3: Chênh lệch | M3: THANH TOÁN POINT
A4: 45263 | B4: 水 | C4: 307096 | D4: 229810 | E4: =C4-D4 -> 77286 | F4: 0 | G4: 0 | H4: =H3+E4+F4 -> 324477 | I4: =C33 -> 12958096 | J4: =G33 -> 487304 | L4: =F33 -> -4118 | M4: 3603
A5: 45264 | B5: 木 | C5: 377140 | D5: 275532 | E5: =C5-D5 -> 101608 | F5: 0 | G5: 0 | H5: =H4+E5+F5 -> 426085 | J5: =J4/I4 -> 0.037606142 | K5: =K4/I4 -> 0 | L5: =L4/I4 -> -0.0003177936 | M5: =M4/I4 -> 0.00027805011
A6: 45265 | B6: 金 | C6: 469040 | D6: 1170189 | E6: =C6-D6 -> -701149 | F6: -575 | G6: 25840 | H6: =H5+E6+F6 -> -275639 | I6: CHI
A7: 45266 | B7: 土 | C7: 323936 | D7: 337938 | E7: =C7-D7 -> -14002 | F7: 0 | G7: 0 | H7: =H6+E7+F7 -> -289641 | I7: NHẬP HÀNG | J7: LƯƠNG | K7: TRẢ HÀNG | L7: Hỗ trợ ship BĐ | M7: TỔNG
A8: 45267 | B8: 日 | C8: 270447 | D8: 297063 | E8: =C8-D8 -> -26616 | F8: -11 | G8: 0 | H8: =H7+E8+F8 -> -316268 | I8: =D33 -> 12575770 | J8: =L16 -> 701500 | K8: =N19 -> 59547 | L8: =J4*0.065 -> 31674.76 | M8: =SUM(I8:L8) -> 13368492
A9: 45268 | B9: 月 | C9: 272640 | D9: 190468 | E9: =C9-D9 -> 82172 | F9: 0 | G9: 44875 | H9: =H8+E9+F9 -> -234096 | I9: LỢI NHUẬN | J9: =I4-M8 -> -410395.76
A10: 45269 | B10: 火 | C10: 337829 | D10: 102855 | E10: =C10-D10 -> 234974 | F10: -147 | G10: 0 | H10: =H9+E10+F10 -> 731 | I10: CHI TIẾT
A11: 45270 | B11: 水 | C11: 433020 | D11: 152559 | E11: =C11-D11 -> 280461 | F11: -55 | G11: 25484 | H11: =H10+E11+F11 -> 281137 | I11: LƯƠNG - 給与
A12: 45271 | B12: 木 | C12: 351361 | D12: 265250 | E12: =C12-D12 -> 86111 | F12: 0 | G12: 57540 | H12: =H11+E12+F12 -> 367248 | I12: A. Giang | J12: A.Thái | K12: C.Hiền | L12: Nhàn | M12: Cưng | N12: Nghĩa
A13: 45272 | B13: 金 | C13: 574555 | D13: 454751 | E13: =C13-D13 -> 119804 | F13: 12 | G13: 0 | H13: =H12+E13+F13 -> 487064 | I13: 250000 | J13: 63150 | K13: 87350 | L13: 0 | M13: 37500 | N13: 198500
A14: 45273 | B14: 土 | C14: 735814 | D14: 415010 | E14: =C14-D14 -> 320804 | F14: -779 | G14: 44320 | H14: =H13+E14+F14 -> 807089 | I14: HỖ TRỢ
A15: 45274 | B15: 日 | C15: 386351 | D15: 144870 | E15: =C15-D15 -> 241481 | F15: 0 | G15: 14720 | H15: =H14+E15+F15 -> 1048570 | I15: 65000
